[45]  2022-05-05 20:12:12.163 | INFO     | sentry_sdk.integrations.logging:sentry_patched_callhandlers:86 - Run run_24ZSZY0X2zTJEQ2YusB2w for labelling function park_roads succeeded over 94088 results.
[47]  2022-05-06 06:31:41.035 | INFO     | sentry_sdk.integrations.logging:sentry_patched_callhandlers:86 - Run run_rUvWBIKa4kSwhestbrwWB for labelling function wharf_building succeeded over 94088 results.
[48]  2022-05-06 06:38:52.506 | INFO     | sentry_sdk.integrations.logging:sentry_patched_callhandlers:86 - Run run_V2qxtNXOg8mPSFblMIjXK for labelling function wharf_building succeeded over 94088 results.
[48]  2022-05-06 06:39:42.892 | INFO     | sentry_sdk.integrations.logging:sentry_patched_callhandlers:86 - Run run_2oYeIrTsNLGeYaRu35IjR for labelling function wharf_building succeeded over 94088 results.
[48]  2022-05-06 06:40:07.057 | INFO     | sentry_sdk.integrations.logging:sentry_patched_callhandlers:86 - Run run_0-3iLQTIJAJKcbjuo3Pw6 for labelling function wharf_road succeeded over 94088 results.
[47]  2022-05-06 06:42:12.593 | INFO     | sentry_sdk.integrations.logging:sentry_patched_callhandlers:86 - Run run_s5jm-CVQzLGadH8SJPE3Q for labelling function wharf_road succeeded over 94088 results.
[49]  2022-05-06 09:35:04.973 | INFO     | sentry_sdk.integrations.logging:sentry_patched_callhandlers:86 - Run run_KPwVWUNwC0FLllK44e0sX for labelling function road_names_basic succeeded over 94088 results.
[41]  2022-05-06 09:39:59.536 | INFO     | sentry_sdk.integrations.logging:sentry_patched_callhandlers:86 - Run run_Z-py9rNef27xWqOrNst5o for labelling function wharf_road succeeded over 94088 results.
[41]  2022-05-06 09:40:44.001 | INFO     | sentry_sdk.integrations.logging:sentry_patched_callhandlers:86 - Run run_AaIP2QhrwqTTgvHe-7xKe for labelling function wharf_road succeeded over 94088 results.
[44]  2022-05-06 09:42:15.070 | INFO     | sentry_sdk.integrations.logging:sentry_patched_callhandlers:86 - Run run_3KZABOUgyHRHb0_LEvn9m for labelling function wharf_building succeeded over 94088 results.
[49]  2022-05-06 09:43:43.874 | INFO     | sentry_sdk.integrations.logging:sentry_patched_callhandlers:86 - Run run_VjTnu-iw4KsY9F1w0-MQo for labelling function mill succeeded over 94088 results.
[47]  2022-05-06 09:44:59.266 | INFO     | sentry_sdk.integrations.logging:sentry_patched_callhandlers:86 - Run run_U9cgxXDe_Ecd9uDaeeIrH for labelling function mill succeeded over 94088 results.
[49]  2022-05-06 09:45:25.320 | ERROR    | sentry_sdk.integrations.logging:sentry_patched_callhandlers:86 - Failed to run labelling function
Traceback (most recent call last):

  File "programmatic/runner/run_functions.py", line 377, in programmatic.runner.run_functions.run_compiled_function_on_datapoint

  File "<string>", line 20, in mill
  File "<string>", line 20, in <listcomp>

  File "pydantic/main.py", line 331, in pydantic.main.BaseModel.__init__

pydantic.error_wrappers.ValidationError: 1 validation error for Span
start
  start index must be non-negative (type=value_error)
[49]  2022-05-06 09:45:25.331 | ERROR    | sentry_sdk.integrations.logging:sentry_patched_callhandlers:86 - Failed to run labelling function
Traceback (most recent call last):

  File "programmatic/runner/run_functions.py", line 377, in programmatic.runner.run_functions.run_compiled_function_on_datapoint

  File "<string>", line 20, in mill
  File "<string>", line 20, in <listcomp>

  File "pydantic/main.py", line 331, in pydantic.main.BaseModel.__init__

pydantic.error_wrappers.ValidationError: 1 validation error for Span
start
  start index must be non-negative (type=value_error)
[49]  2022-05-06 09:45:25.338 | ERROR    | sentry_sdk.integrations.logging:sentry_patched_callhandlers:86 - Failed to run labelling function
Traceback (most recent call last):

  File "programmatic/runner/run_functions.py", line 377, in programmatic.runner.run_functions.run_compiled_function_on_datapoint

  File "<string>", line 20, in mill
  File "<string>", line 20, in <listcomp>

  File "pydantic/main.py", line 331, in pydantic.main.BaseModel.__init__

pydantic.error_wrappers.ValidationError: 1 validation error for Span
start
  start index must be non-negative (type=value_error)
[49]  2022-05-06 09:45:25.340 | DEBUG    | sentry_sdk.integrations.logging:sentry_patched_callhandlers:86 - Starting new HTTPS connection (1): o427213.ingest.sentry.io:443
[49]  2022-05-06 09:45:25.344 | ERROR    | sentry_sdk.integrations.logging:sentry_patched_callhandlers:86 - Failed to run labelling function
Traceback (most recent call last):

  File "programmatic/runner/run_functions.py", line 377, in programmatic.runner.run_functions.run_compiled_function_on_datapoint

  File "<string>", line 20, in mill
  File "<string>", line 20, in <listcomp>

  File "pydantic/main.py", line 331, in pydantic.main.BaseModel.__init__

pydantic.error_wrappers.ValidationError: 1 validation error for Span
start
  start index must be non-negative (type=value_error)
[49]  2022-05-06 09:45:25.349 | ERROR    | sentry_sdk.integrations.logging:sentry_patched_callhandlers:86 - Failed to run labelling function
Traceback (most recent call last):

  File "programmatic/runner/run_functions.py", line 377, in programmatic.runner.run_functions.run_compiled_function_on_datapoint

  File "<string>", line 20, in mill
  File "<string>", line 20, in <listcomp>

  File "pydantic/main.py", line 331, in pydantic.main.BaseModel.__init__

pydantic.error_wrappers.ValidationError: 1 validation error for Span
start
  start index must be non-negative (type=value_error)
[49]  2022-05-06 09:45:25.353 | ERROR    | sentry_sdk.integrations.logging:sentry_patched_callhandlers:86 - Failed to run labelling function
Traceback (most recent call last):

  File "programmatic/runner/run_functions.py", line 377, in programmatic.runner.run_functions.run_compiled_function_on_datapoint

  File "<string>", line 20, in mill
  File "<string>", line 20, in <listcomp>

  File "pydantic/main.py", line 331, in pydantic.main.BaseModel.__init__

pydantic.error_wrappers.ValidationError: 1 validation error for Span
start
  start index must be non-negative (type=value_error)
[49]  2022-05-06 09:45:25.359 | ERROR    | sentry_sdk.integrations.logging:sentry_patched_callhandlers:86 - Failed to run labelling function
Traceback (most recent call last):

  File "programmatic/runner/run_functions.py", line 377, in programmatic.runner.run_functions.run_compiled_function_on_datapoint

  File "<string>", line 20, in mill
  File "<string>", line 20, in <listcomp>

  File "pydantic/main.py", line 331, in pydantic.main.BaseModel.__init__

pydantic.error_wrappers.ValidationError: 1 validation error for Span
start
  start index must be non-negative (type=value_error)
[49]  2022-05-06 09:45:25.412 | ERROR    | sentry_sdk.integrations.logging:sentry_patched_callhandlers:86 - Failed to run labelling function
Traceback (most recent call last):

  File "programmatic/runner/run_functions.py", line 377, in programmatic.runner.run_functions.run_compiled_function_on_datapoint

  File "<string>", line 20, in mill
  File "<string>", line 20, in <listcomp>

  File "pydantic/main.py", line 331, in pydantic.main.BaseModel.__init__

pydantic.error_wrappers.ValidationError: 1 validation error for Span
start
  start index must be non-negative (type=value_error)
[49]  2022-05-06 09:45:25.441 | ERROR    | sentry_sdk.integrations.logging:sentry_patched_callhandlers:86 - Failed to run labelling function
Traceback (most recent call last):

  File "programmatic/runner/run_functions.py", line 377, in programmatic.runner.run_functions.run_compiled_function_on_datapoint

  File "<string>", line 20, in mill
  File "<string>", line 20, in <listcomp>

  File "pydantic/main.py", line 331, in pydantic.main.BaseModel.__init__

pydantic.error_wrappers.ValidationError: 1 validation error for Span
start
  start index must be non-negative (type=value_error)
[49]  2022-05-06 09:45:25.454 | DEBUG    | sentry_sdk.integrations.logging:sentry_patched_callhandlers:86 - https://o427213.ingest.sentry.io:443 "POST /api/6142069/store/ HTTP/1.1" 200 41
[49]  2022-05-06 09:45:25.481 | ERROR    | sentry_sdk.integrations.logging:sentry_patched_callhandlers:86 - Failed to run labelling function
Traceback (most recent call last):

  File "programmatic/runner/run_functions.py", line 377, in programmatic.runner.run_functions.run_compiled_function_on_datapoint

  File "<string>", line 20, in mill
  File "<string>", line 20, in <listcomp>

  File "pydantic/main.py", line 331, in pydantic.main.BaseModel.__init__

pydantic.error_wrappers.ValidationError: 1 validation error for Span
start
  start index must be non-negative (type=value_error)
[49]  2022-05-06 09:45:25.494 | DEBUG    | sentry_sdk.integrations.logging:sentry_patched_callhandlers:86 - https://o427213.ingest.sentry.io:443 "POST /api/6142069/store/ HTTP/1.1" 200 41
[49]  2022-05-06 09:45:25.583 | DEBUG    | sentry_sdk.integrations.logging:sentry_patched_callhandlers:86 - https://o427213.ingest.sentry.io:443 "POST /api/6142069/store/ HTTP/1.1" 200 41
[49]  2022-05-06 09:45:25.620 | ERROR    | sentry_sdk.integrations.logging:sentry_patched_callhandlers:86 - Failed to run labelling function
Traceback (most recent call last):

  File "programmatic/runner/run_functions.py", line 377, in programmatic.runner.run_functions.run_compiled_function_on_datapoint

  File "<string>", line 20, in mill
  File "<string>", line 20, in <listcomp>

  File "pydantic/main.py", line 331, in pydantic.main.BaseModel.__init__

pydantic.error_wrappers.ValidationError: 1 validation error for Span
start
  start index must be non-negative (type=value_error)
[49]  2022-05-06 09:45:25.625 | ERROR    | sentry_sdk.integrations.logging:sentry_patched_callhandlers:86 - Failed to run labelling function
Traceback (most recent call last):

  File "programmatic/runner/run_functions.py", line 377, in programmatic.runner.run_functions.run_compiled_function_on_datapoint

  File "<string>", line 20, in mill
  File "<string>", line 20, in <listcomp>

  File "pydantic/main.py", line 331, in pydantic.main.BaseModel.__init__

pydantic.error_wrappers.ValidationError: 1 validation error for Span
start
  start index must be non-negative (type=value_error)
[49]  2022-05-06 09:45:25.640 | ERROR    | sentry_sdk.integrations.logging:sentry_patched_callhandlers:86 - Failed to run labelling function
Traceback (most recent call last):

  File "programmatic/runner/run_functions.py", line 377, in programmatic.runner.run_functions.run_compiled_function_on_datapoint

  File "<string>", line 20, in mill
  File "<string>", line 20, in <listcomp>

  File "pydantic/main.py", line 331, in pydantic.main.BaseModel.__init__

pydantic.error_wrappers.ValidationError: 1 validation error for Span
start
  start index must be non-negative (type=value_error)
[49]  2022-05-06 09:45:25.643 | DEBUG    | sentry_sdk.integrations.logging:sentry_patched_callhandlers:86 - https://o427213.ingest.sentry.io:443 "POST /api/6142069/store/ HTTP/1.1" 200 41
[49]  2022-05-06 09:45:25.648 | ERROR    | sentry_sdk.integrations.logging:sentry_patched_callhandlers:86 - Failed to run labelling function
Traceback (most recent call last):

  File "programmatic/runner/run_functions.py", line 377, in programmatic.runner.run_functions.run_compiled_function_on_datapoint

  File "<string>", line 20, in mill
  File "<string>", line 20, in <listcomp>

  File "pydantic/main.py", line 331, in pydantic.main.BaseModel.__init__

pydantic.error_wrappers.ValidationError: 1 validation error for Span
start
  start index must be non-negative (type=value_error)
[49]  2022-05-06 09:45:25.658 | ERROR    | sentry_sdk.integrations.logging:sentry_patched_callhandlers:86 - Failed to run labelling function
Traceback (most recent call last):

  File "programmatic/runner/run_functions.py", line 377, in programmatic.runner.run_functions.run_compiled_function_on_datapoint

  File "<string>", line 20, in mill
  File "<string>", line 20, in <listcomp>

  File "pydantic/main.py", line 331, in pydantic.main.BaseModel.__init__

pydantic.error_wrappers.ValidationError: 1 validation error for Span
start
  start index must be non-negative (type=value_error)
[49]  2022-05-06 09:45:25.681 | DEBUG    | sentry_sdk.integrations.logging:sentry_patched_callhandlers:86 - https://o427213.ingest.sentry.io:443 "POST /api/6142069/store/ HTTP/1.1" 200 41
[49]  2022-05-06 09:45:25.859 | DEBUG    | sentry_sdk.integrations.logging:sentry_patched_callhandlers:86 - https://o427213.ingest.sentry.io:443 "POST /api/6142069/store/ HTTP/1.1" 200 41
[49]  2022-05-06 09:45:25.887 | ERROR    | sentry_sdk.integrations.logging:sentry_patched_callhandlers:86 - Failed to run labelling function
Traceback (most recent call last):

  File "programmatic/runner/run_functions.py", line 377, in programmatic.runner.run_functions.run_compiled_function_on_datapoint

  File "<string>", line 20, in mill
  File "<string>", line 20, in <listcomp>

  File "pydantic/main.py", line 331, in pydantic.main.BaseModel.__init__

pydantic.error_wrappers.ValidationError: 1 validation error for Span
start
  start index must be non-negative (type=value_error)
[49]  2022-05-06 09:45:25.896 | ERROR    | sentry_sdk.integrations.logging:sentry_patched_callhandlers:86 - Failed to run labelling function
Traceback (most recent call last):

  File "programmatic/runner/run_functions.py", line 377, in programmatic.runner.run_functions.run_compiled_function_on_datapoint

  File "<string>", line 20, in mill
  File "<string>", line 20, in <listcomp>

  File "pydantic/main.py", line 331, in pydantic.main.BaseModel.__init__

pydantic.error_wrappers.ValidationError: 1 validation error for Span
start
  start index must be non-negative (type=value_error)
[49]  2022-05-06 09:45:25.905 | ERROR    | sentry_sdk.integrations.logging:sentry_patched_callhandlers:86 - Failed to run labelling function
Traceback (most recent call last):

  File "programmatic/runner/run_functions.py", line 377, in programmatic.runner.run_functions.run_compiled_function_on_datapoint

  File "<string>", line 20, in mill
  File "<string>", line 20, in <listcomp>

  File "pydantic/main.py", line 331, in pydantic.main.BaseModel.__init__

pydantic.error_wrappers.ValidationError: 1 validation error for Span
start
  start index must be non-negative (type=value_error)
[49]  2022-05-06 09:45:25.914 | DEBUG    | sentry_sdk.integrations.logging:sentry_patched_callhandlers:86 - https://o427213.ingest.sentry.io:443 "POST /api/6142069/store/ HTTP/1.1" 200 41
[49]  2022-05-06 09:45:25.916 | ERROR    | sentry_sdk.integrations.logging:sentry_patched_callhandlers:86 - Failed to run labelling function
Traceback (most recent call last):

  File "programmatic/runner/run_functions.py", line 377, in programmatic.runner.run_functions.run_compiled_function_on_datapoint

  File "<string>", line 20, in mill
  File "<string>", line 20, in <listcomp>

  File "pydantic/main.py", line 331, in pydantic.main.BaseModel.__init__

pydantic.error_wrappers.ValidationError: 1 validation error for Span
start
  start index must be non-negative (type=value_error)
[49]  2022-05-06 09:45:25.933 | ERROR    | sentry_sdk.integrations.logging:sentry_patched_callhandlers:86 - Failed to run labelling function
Traceback (most recent call last):

  File "programmatic/runner/run_functions.py", line 377, in programmatic.runner.run_functions.run_compiled_function_on_datapoint

  File "<string>", line 20, in mill
  File "<string>", line 20, in <listcomp>

  File "pydantic/main.py", line 331, in pydantic.main.BaseModel.__init__

pydantic.error_wrappers.ValidationError: 1 validation error for Span
start
  start index must be non-negative (type=value_error)
[49]  2022-05-06 09:45:25.942 | ERROR    | sentry_sdk.integrations.logging:sentry_patched_callhandlers:86 - Failed to run labelling function
Traceback (most recent call last):

  File "programmatic/runner/run_functions.py", line 377, in programmatic.runner.run_functions.run_compiled_function_on_datapoint

  File "<string>", line 20, in mill
  File "<string>", line 20, in <listcomp>

  File "pydantic/main.py", line 331, in pydantic.main.BaseModel.__init__

pydantic.error_wrappers.ValidationError: 1 validation error for Span
start
  start index must be non-negative (type=value_error)
[49]  2022-05-06 09:45:25.970 | DEBUG    | sentry_sdk.integrations.logging:sentry_patched_callhandlers:86 - https://o427213.ingest.sentry.io:443 "POST /api/6142069/store/ HTTP/1.1" 200 41
[49]  2022-05-06 09:45:25.975 | ERROR    | sentry_sdk.integrations.logging:sentry_patched_callhandlers:86 - Failed to run labelling function
Traceback (most recent call last):

  File "programmatic/runner/run_functions.py", line 377, in programmatic.runner.run_functions.run_compiled_function_on_datapoint

  File "<string>", line 20, in mill
  File "<string>", line 20, in <listcomp>

  File "pydantic/main.py", line 331, in pydantic.main.BaseModel.__init__

pydantic.error_wrappers.ValidationError: 1 validation error for Span
start
  start index must be non-negative (type=value_error)
[49]  2022-05-06 09:45:25.996 | ERROR    | sentry_sdk.integrations.logging:sentry_patched_callhandlers:86 - Failed to run labelling function
Traceback (most recent call last):

  File "programmatic/runner/run_functions.py", line 377, in programmatic.runner.run_functions.run_compiled_function_on_datapoint

  File "<string>", line 20, in mill
  File "<string>", line 20, in <listcomp>

  File "pydantic/main.py", line 331, in pydantic.main.BaseModel.__init__

pydantic.error_wrappers.ValidationError: 1 validation error for Span
start
  start index must be non-negative (type=value_error)
[49]  2022-05-06 09:45:26.022 | DEBUG    | sentry_sdk.integrations.logging:sentry_patched_callhandlers:86 - https://o427213.ingest.sentry.io:443 "POST /api/6142069/store/ HTTP/1.1" 200 41
[49]  2022-05-06 09:45:26.046 | ERROR    | sentry_sdk.integrations.logging:sentry_patched_callhandlers:86 - Failed to run labelling function
Traceback (most recent call last):

  File "programmatic/runner/run_functions.py", line 377, in programmatic.runner.run_functions.run_compiled_function_on_datapoint

  File "<string>", line 20, in mill
  File "<string>", line 20, in <listcomp>

  File "pydantic/main.py", line 331, in pydantic.main.BaseModel.__init__

pydantic.error_wrappers.ValidationError: 1 validation error for Span
start
  start index must be non-negative (type=value_error)
[49]  2022-05-06 09:45:26.052 | ERROR    | sentry_sdk.integrations.logging:sentry_patched_callhandlers:86 - Failed to run labelling function
Traceback (most recent call last):

  File "programmatic/runner/run_functions.py", line 377, in programmatic.runner.run_functions.run_compiled_function_on_datapoint

  File "<string>", line 20, in mill
  File "<string>", line 20, in <listcomp>

  File "pydantic/main.py", line 331, in pydantic.main.BaseModel.__init__

pydantic.error_wrappers.ValidationError: 1 validation error for Span
start
  start index must be non-negative (type=value_error)
[49]  2022-05-06 09:45:26.074 | ERROR    | sentry_sdk.integrations.logging:sentry_patched_callhandlers:86 - Failed to run labelling function
Traceback (most recent call last):

  File "programmatic/runner/run_functions.py", line 377, in programmatic.runner.run_functions.run_compiled_function_on_datapoint

  File "<string>", line 20, in mill
  File "<string>", line 20, in <listcomp>

  File "pydantic/main.py", line 331, in pydantic.main.BaseModel.__init__

pydantic.error_wrappers.ValidationError: 1 validation error for Span
start
  start index must be non-negative (type=value_error)
[49]  2022-05-06 09:45:26.080 | ERROR    | sentry_sdk.integrations.logging:sentry_patched_callhandlers:86 - Failed to run labelling function
Traceback (most recent call last):

  File "programmatic/runner/run_functions.py", line 377, in programmatic.runner.run_functions.run_compiled_function_on_datapoint

  File "<string>", line 20, in mill
  File "<string>", line 20, in <listcomp>

  File "pydantic/main.py", line 331, in pydantic.main.BaseModel.__init__

pydantic.error_wrappers.ValidationError: 1 validation error for Span
start
  start index must be non-negative (type=value_error)
[49]  2022-05-06 09:45:26.086 | DEBUG    | sentry_sdk.integrations.logging:sentry_patched_callhandlers:86 - https://o427213.ingest.sentry.io:443 "POST /api/6142069/store/ HTTP/1.1" 200 41
[49]  2022-05-06 09:45:26.088 | ERROR    | sentry_sdk.integrations.logging:sentry_patched_callhandlers:86 - Failed to run labelling function
Traceback (most recent call last):

  File "programmatic/runner/run_functions.py", line 377, in programmatic.runner.run_functions.run_compiled_function_on_datapoint

  File "<string>", line 20, in mill
  File "<string>", line 20, in <listcomp>

  File "pydantic/main.py", line 331, in pydantic.main.BaseModel.__init__

pydantic.error_wrappers.ValidationError: 1 validation error for Span
start
  start index must be non-negative (type=value_error)
[49]  2022-05-06 09:45:26.109 | ERROR    | sentry_sdk.integrations.logging:sentry_patched_callhandlers:86 - Failed to run labelling function
Traceback (most recent call last):

  File "programmatic/runner/run_functions.py", line 377, in programmatic.runner.run_functions.run_compiled_function_on_datapoint

  File "<string>", line 20, in mill
  File "<string>", line 20, in <listcomp>

  File "pydantic/main.py", line 331, in pydantic.main.BaseModel.__init__

pydantic.error_wrappers.ValidationError: 1 validation error for Span
start
  start index must be non-negative (type=value_error)
[49]  2022-05-06 09:45:26.116 | ERROR    | sentry_sdk.integrations.logging:sentry_patched_callhandlers:86 - Failed to run labelling function
Traceback (most recent call last):

  File "programmatic/runner/run_functions.py", line 377, in programmatic.runner.run_functions.run_compiled_function_on_datapoint

  File "<string>", line 20, in mill
  File "<string>", line 20, in <listcomp>

  File "pydantic/main.py", line 331, in pydantic.main.BaseModel.__init__

pydantic.error_wrappers.ValidationError: 1 validation error for Span
start
  start index must be non-negative (type=value_error)
[49]  2022-05-06 09:45:26.118 | DEBUG    | sentry_sdk.integrations.logging:sentry_patched_callhandlers:86 - https://o427213.ingest.sentry.io:443 "POST /api/6142069/store/ HTTP/1.1" 200 41
[49]  2022-05-06 09:45:26.130 | ERROR    | sentry_sdk.integrations.logging:sentry_patched_callhandlers:86 - Failed to run labelling function
Traceback (most recent call last):

  File "programmatic/runner/run_functions.py", line 377, in programmatic.runner.run_functions.run_compiled_function_on_datapoint

  File "<string>", line 20, in mill
  File "<string>", line 20, in <listcomp>

  File "pydantic/main.py", line 331, in pydantic.main.BaseModel.__init__

pydantic.error_wrappers.ValidationError: 1 validation error for Span
start
  start index must be non-negative (type=value_error)
[49]  2022-05-06 09:45:26.144 | ERROR    | sentry_sdk.integrations.logging:sentry_patched_callhandlers:86 - Failed to run labelling function
Traceback (most recent call last):

  File "programmatic/runner/run_functions.py", line 377, in programmatic.runner.run_functions.run_compiled_function_on_datapoint

  File "<string>", line 20, in mill
  File "<string>", line 20, in <listcomp>

  File "pydantic/main.py", line 331, in pydantic.main.BaseModel.__init__

pydantic.error_wrappers.ValidationError: 1 validation error for Span
start
  start index must be non-negative (type=value_error)
[49]  2022-05-06 09:45:26.172 | DEBUG    | sentry_sdk.integrations.logging:sentry_patched_callhandlers:86 - https://o427213.ingest.sentry.io:443 "POST /api/6142069/store/ HTTP/1.1" 200 41
[49]  2022-05-06 09:45:26.186 | ERROR    | sentry_sdk.integrations.logging:sentry_patched_callhandlers:86 - Failed to run labelling function
Traceback (most recent call last):

  File "programmatic/runner/run_functions.py", line 377, in programmatic.runner.run_functions.run_compiled_function_on_datapoint

  File "<string>", line 20, in mill
  File "<string>", line 20, in <listcomp>

  File "pydantic/main.py", line 331, in pydantic.main.BaseModel.__init__

pydantic.error_wrappers.ValidationError: 1 validation error for Span
start
  start index must be non-negative (type=value_error)
[49]  2022-05-06 09:45:26.223 | DEBUG    | sentry_sdk.integrations.logging:sentry_patched_callhandlers:86 - https://o427213.ingest.sentry.io:443 "POST /api/6142069/store/ HTTP/1.1" 200 41
[49]  2022-05-06 09:45:26.275 | DEBUG    | sentry_sdk.integrations.logging:sentry_patched_callhandlers:86 - https://o427213.ingest.sentry.io:443 "POST /api/6142069/store/ HTTP/1.1" 200 41
[49]  2022-05-06 09:45:26.289 | ERROR    | sentry_sdk.integrations.logging:sentry_patched_callhandlers:86 - Failed to run labelling function
Traceback (most recent call last):

  File "programmatic/runner/run_functions.py", line 377, in programmatic.runner.run_functions.run_compiled_function_on_datapoint

  File "<string>", line 20, in mill
  File "<string>", line 20, in <listcomp>

  File "pydantic/main.py", line 331, in pydantic.main.BaseModel.__init__

pydantic.error_wrappers.ValidationError: 1 validation error for Span
start
  start index must be non-negative (type=value_error)
[49]  2022-05-06 09:45:26.298 | ERROR    | sentry_sdk.integrations.logging:sentry_patched_callhandlers:86 - Failed to run labelling function
Traceback (most recent call last):

  File "programmatic/runner/run_functions.py", line 377, in programmatic.runner.run_functions.run_compiled_function_on_datapoint

  File "<string>", line 20, in mill
  File "<string>", line 20, in <listcomp>

  File "pydantic/main.py", line 331, in pydantic.main.BaseModel.__init__

pydantic.error_wrappers.ValidationError: 1 validation error for Span
start
  start index must be non-negative (type=value_error)
[49]  2022-05-06 09:45:26.307 | ERROR    | sentry_sdk.integrations.logging:sentry_patched_callhandlers:86 - Failed to run labelling function
Traceback (most recent call last):

  File "programmatic/runner/run_functions.py", line 377, in programmatic.runner.run_functions.run_compiled_function_on_datapoint

  File "<string>", line 20, in mill
  File "<string>", line 20, in <listcomp>

  File "pydantic/main.py", line 331, in pydantic.main.BaseModel.__init__

pydantic.error_wrappers.ValidationError: 1 validation error for Span
start
  start index must be non-negative (type=value_error)
[49]  2022-05-06 09:45:26.315 | ERROR    | sentry_sdk.integrations.logging:sentry_patched_callhandlers:86 - Failed to run labelling function
Traceback (most recent call last):

  File "programmatic/runner/run_functions.py", line 377, in programmatic.runner.run_functions.run_compiled_function_on_datapoint

  File "<string>", line 20, in mill
  File "<string>", line 20, in <listcomp>

  File "pydantic/main.py", line 331, in pydantic.main.BaseModel.__init__

pydantic.error_wrappers.ValidationError: 1 validation error for Span
start
  start index must be non-negative (type=value_error)
[49]  2022-05-06 09:45:26.317 | DEBUG    | sentry_sdk.integrations.logging:sentry_patched_callhandlers:86 - https://o427213.ingest.sentry.io:443 "POST /api/6142069/store/ HTTP/1.1" 200 41
[49]  2022-05-06 09:45:26.336 | ERROR    | sentry_sdk.integrations.logging:sentry_patched_callhandlers:86 - Failed to run labelling function
Traceback (most recent call last):

  File "programmatic/runner/run_functions.py", line 377, in programmatic.runner.run_functions.run_compiled_function_on_datapoint

  File "<string>", line 20, in mill
  File "<string>", line 20, in <listcomp>

  File "pydantic/main.py", line 331, in pydantic.main.BaseModel.__init__

pydantic.error_wrappers.ValidationError: 1 validation error for Span
start
  start index must be non-negative (type=value_error)
[49]  2022-05-06 09:45:26.347 | ERROR    | sentry_sdk.integrations.logging:sentry_patched_callhandlers:86 - Failed to run labelling function
Traceback (most recent call last):

  File "programmatic/runner/run_functions.py", line 377, in programmatic.runner.run_functions.run_compiled_function_on_datapoint

  File "<string>", line 20, in mill
  File "<string>", line 20, in <listcomp>

  File "pydantic/main.py", line 331, in pydantic.main.BaseModel.__init__

pydantic.error_wrappers.ValidationError: 1 validation error for Span
start
  start index must be non-negative (type=value_error)
[49]  2022-05-06 09:45:26.356 | DEBUG    | sentry_sdk.integrations.logging:sentry_patched_callhandlers:86 - https://o427213.ingest.sentry.io:443 "POST /api/6142069/store/ HTTP/1.1" 200 41
[49]  2022-05-06 09:45:26.358 | ERROR    | sentry_sdk.integrations.logging:sentry_patched_callhandlers:86 - Failed to run labelling function
Traceback (most recent call last):

  File "programmatic/runner/run_functions.py", line 377, in programmatic.runner.run_functions.run_compiled_function_on_datapoint

  File "<string>", line 20, in mill
  File "<string>", line 20, in <listcomp>

  File "pydantic/main.py", line 331, in pydantic.main.BaseModel.__init__

pydantic.error_wrappers.ValidationError: 1 validation error for Span
start
  start index must be non-negative (type=value_error)
[49]  2022-05-06 09:45:26.371 | ERROR    | sentry_sdk.integrations.logging:sentry_patched_callhandlers:86 - Failed to run labelling function
Traceback (most recent call last):

  File "programmatic/runner/run_functions.py", line 377, in programmatic.runner.run_functions.run_compiled_function_on_datapoint

  File "<string>", line 20, in mill
  File "<string>", line 20, in <listcomp>

  File "pydantic/main.py", line 331, in pydantic.main.BaseModel.__init__

pydantic.error_wrappers.ValidationError: 1 validation error for Span
start
  start index must be non-negative (type=value_error)
[49]  2022-05-06 09:45:26.387 | ERROR    | sentry_sdk.integrations.logging:sentry_patched_callhandlers:86 - Failed to run labelling function
Traceback (most recent call last):

  File "programmatic/runner/run_functions.py", line 377, in programmatic.runner.run_functions.run_compiled_function_on_datapoint

  File "<string>", line 20, in mill
  File "<string>", line 20, in <listcomp>

  File "pydantic/main.py", line 331, in pydantic.main.BaseModel.__init__

pydantic.error_wrappers.ValidationError: 1 validation error for Span
start
  start index must be non-negative (type=value_error)
[49]  2022-05-06 09:45:26.389 | DEBUG    | sentry_sdk.integrations.logging:sentry_patched_callhandlers:86 - https://o427213.ingest.sentry.io:443 "POST /api/6142069/store/ HTTP/1.1" 200 41
[49]  2022-05-06 09:45:26.406 | ERROR    | sentry_sdk.integrations.logging:sentry_patched_callhandlers:86 - Failed to run labelling function
Traceback (most recent call last):

  File "programmatic/runner/run_functions.py", line 377, in programmatic.runner.run_functions.run_compiled_function_on_datapoint

  File "<string>", line 20, in mill
  File "<string>", line 20, in <listcomp>

  File "pydantic/main.py", line 331, in pydantic.main.BaseModel.__init__

pydantic.error_wrappers.ValidationError: 1 validation error for Span
start
  start index must be non-negative (type=value_error)
[49]  2022-05-06 09:45:26.448 | DEBUG    | sentry_sdk.integrations.logging:sentry_patched_callhandlers:86 - https://o427213.ingest.sentry.io:443 "POST /api/6142069/store/ HTTP/1.1" 200 41
[49]  2022-05-06 09:45:26.513 | ERROR    | sentry_sdk.integrations.logging:sentry_patched_callhandlers:86 - Failed to run labelling function
Traceback (most recent call last):

  File "programmatic/runner/run_functions.py", line 377, in programmatic.runner.run_functions.run_compiled_function_on_datapoint

  File "<string>", line 20, in mill
  File "<string>", line 20, in <listcomp>

  File "pydantic/main.py", line 331, in pydantic.main.BaseModel.__init__

pydantic.error_wrappers.ValidationError: 1 validation error for Span
start
  start index must be non-negative (type=value_error)
[49]  2022-05-06 09:45:26.532 | DEBUG    | sentry_sdk.integrations.logging:sentry_patched_callhandlers:86 - https://o427213.ingest.sentry.io:443 "POST /api/6142069/store/ HTTP/1.1" 200 41
[49]  2022-05-06 09:45:26.551 | ERROR    | sentry_sdk.integrations.logging:sentry_patched_callhandlers:86 - Failed to run labelling function
Traceback (most recent call last):

  File "programmatic/runner/run_functions.py", line 377, in programmatic.runner.run_functions.run_compiled_function_on_datapoint

  File "<string>", line 20, in mill
  File "<string>", line 20, in <listcomp>

  File "pydantic/main.py", line 331, in pydantic.main.BaseModel.__init__

pydantic.error_wrappers.ValidationError: 1 validation error for Span
start
  start index must be non-negative (type=value_error)
[49]  2022-05-06 09:45:26.557 | ERROR    | sentry_sdk.integrations.logging:sentry_patched_callhandlers:86 - Failed to run labelling function
Traceback (most recent call last):

  File "programmatic/runner/run_functions.py", line 377, in programmatic.runner.run_functions.run_compiled_function_on_datapoint

  File "<string>", line 20, in mill
  File "<string>", line 20, in <listcomp>

  File "pydantic/main.py", line 331, in pydantic.main.BaseModel.__init__

pydantic.error_wrappers.ValidationError: 1 validation error for Span
start
  start index must be non-negative (type=value_error)
[49]  2022-05-06 09:45:26.587 | DEBUG    | sentry_sdk.integrations.logging:sentry_patched_callhandlers:86 - https://o427213.ingest.sentry.io:443 "POST /api/6142069/store/ HTTP/1.1" 200 41
[49]  2022-05-06 09:45:26.789 | ERROR    | sentry_sdk.integrations.logging:sentry_patched_callhandlers:86 - Failed to run labelling function
Traceback (most recent call last):

  File "programmatic/runner/run_functions.py", line 377, in programmatic.runner.run_functions.run_compiled_function_on_datapoint

  File "<string>", line 20, in mill
  File "<string>", line 20, in <listcomp>

  File "pydantic/main.py", line 331, in pydantic.main.BaseModel.__init__

pydantic.error_wrappers.ValidationError: 1 validation error for Span
start
  start index must be non-negative (type=value_error)
[49]  2022-05-06 09:45:26.809 | DEBUG    | sentry_sdk.integrations.logging:sentry_patched_callhandlers:86 - https://o427213.ingest.sentry.io:443 "POST /api/6142069/store/ HTTP/1.1" 200 41
[49]  2022-05-06 09:45:26.825 | ERROR    | sentry_sdk.integrations.logging:sentry_patched_callhandlers:86 - Failed to run labelling function
Traceback (most recent call last):

  File "programmatic/runner/run_functions.py", line 377, in programmatic.runner.run_functions.run_compiled_function_on_datapoint

  File "<string>", line 20, in mill
  File "<string>", line 20, in <listcomp>

  File "pydantic/main.py", line 331, in pydantic.main.BaseModel.__init__

pydantic.error_wrappers.ValidationError: 1 validation error for Span
start
  start index must be non-negative (type=value_error)
[49]  2022-05-06 09:45:26.839 | ERROR    | sentry_sdk.integrations.logging:sentry_patched_callhandlers:86 - Failed to run labelling function
Traceback (most recent call last):

  File "programmatic/runner/run_functions.py", line 377, in programmatic.runner.run_functions.run_compiled_function_on_datapoint

  File "<string>", line 20, in mill
  File "<string>", line 20, in <listcomp>

  File "pydantic/main.py", line 331, in pydantic.main.BaseModel.__init__

pydantic.error_wrappers.ValidationError: 1 validation error for Span
start
  start index must be non-negative (type=value_error)
[49]  2022-05-06 09:45:26.849 | ERROR    | sentry_sdk.integrations.logging:sentry_patched_callhandlers:86 - Failed to run labelling function
Traceback (most recent call last):

  File "programmatic/runner/run_functions.py", line 377, in programmatic.runner.run_functions.run_compiled_function_on_datapoint

  File "<string>", line 20, in mill
  File "<string>", line 20, in <listcomp>

  File "pydantic/main.py", line 331, in pydantic.main.BaseModel.__init__

pydantic.error_wrappers.ValidationError: 1 validation error for Span
start
  start index must be non-negative (type=value_error)
[49]  2022-05-06 09:45:26.856 | DEBUG    | sentry_sdk.integrations.logging:sentry_patched_callhandlers:86 - https://o427213.ingest.sentry.io:443 "POST /api/6142069/store/ HTTP/1.1" 200 41
[49]  2022-05-06 09:45:26.861 | ERROR    | sentry_sdk.integrations.logging:sentry_patched_callhandlers:86 - Failed to run labelling function
Traceback (most recent call last):

  File "programmatic/runner/run_functions.py", line 377, in programmatic.runner.run_functions.run_compiled_function_on_datapoint

  File "<string>", line 20, in mill
  File "<string>", line 20, in <listcomp>

  File "pydantic/main.py", line 331, in pydantic.main.BaseModel.__init__

pydantic.error_wrappers.ValidationError: 1 validation error for Span
start
  start index must be non-negative (type=value_error)
[49]  2022-05-06 09:45:26.877 | ERROR    | sentry_sdk.integrations.logging:sentry_patched_callhandlers:86 - Failed to run labelling function
Traceback (most recent call last):

  File "programmatic/runner/run_functions.py", line 377, in programmatic.runner.run_functions.run_compiled_function_on_datapoint

  File "<string>", line 20, in mill
  File "<string>", line 20, in <listcomp>

  File "pydantic/main.py", line 331, in pydantic.main.BaseModel.__init__

pydantic.error_wrappers.ValidationError: 1 validation error for Span
start
  start index must be non-negative (type=value_error)
[49]  2022-05-06 09:45:26.887 | ERROR    | sentry_sdk.integrations.logging:sentry_patched_callhandlers:86 - Failed to run labelling function
Traceback (most recent call last):

  File "programmatic/runner/run_functions.py", line 377, in programmatic.runner.run_functions.run_compiled_function_on_datapoint

  File "<string>", line 20, in mill
  File "<string>", line 20, in <listcomp>

  File "pydantic/main.py", line 331, in pydantic.main.BaseModel.__init__

pydantic.error_wrappers.ValidationError: 1 validation error for Span
start
  start index must be non-negative (type=value_error)
[49]  2022-05-06 09:45:26.894 | DEBUG    | sentry_sdk.integrations.logging:sentry_patched_callhandlers:86 - https://o427213.ingest.sentry.io:443 "POST /api/6142069/store/ HTTP/1.1" 200 41
[49]  2022-05-06 09:45:26.945 | DEBUG    | sentry_sdk.integrations.logging:sentry_patched_callhandlers:86 - https://o427213.ingest.sentry.io:443 "POST /api/6142069/store/ HTTP/1.1" 200 41
[49]  2022-05-06 09:45:26.960 | ERROR    | sentry_sdk.integrations.logging:sentry_patched_callhandlers:86 - Failed to run labelling function
Traceback (most recent call last):

  File "programmatic/runner/run_functions.py", line 377, in programmatic.runner.run_functions.run_compiled_function_on_datapoint

  File "<string>", line 20, in mill
  File "<string>", line 20, in <listcomp>

  File "pydantic/main.py", line 331, in pydantic.main.BaseModel.__init__

pydantic.error_wrappers.ValidationError: 1 validation error for Span
start
  start index must be non-negative (type=value_error)
[49]  2022-05-06 09:45:27.011 | DEBUG    | sentry_sdk.integrations.logging:sentry_patched_callhandlers:86 - https://o427213.ingest.sentry.io:443 "POST /api/6142069/store/ HTTP/1.1" 200 41
[49]  2022-05-06 09:45:27.035 | ERROR    | sentry_sdk.integrations.logging:sentry_patched_callhandlers:86 - Failed to run labelling function
Traceback (most recent call last):

  File "programmatic/runner/run_functions.py", line 377, in programmatic.runner.run_functions.run_compiled_function_on_datapoint

  File "<string>", line 20, in mill
  File "<string>", line 20, in <listcomp>

  File "pydantic/main.py", line 331, in pydantic.main.BaseModel.__init__

pydantic.error_wrappers.ValidationError: 1 validation error for Span
start
  start index must be non-negative (type=value_error)
[49]  2022-05-06 09:45:27.045 | ERROR    | sentry_sdk.integrations.logging:sentry_patched_callhandlers:86 - Failed to run labelling function
Traceback (most recent call last):

  File "programmatic/runner/run_functions.py", line 377, in programmatic.runner.run_functions.run_compiled_function_on_datapoint

  File "<string>", line 20, in mill
  File "<string>", line 20, in <listcomp>

  File "pydantic/main.py", line 331, in pydantic.main.BaseModel.__init__

pydantic.error_wrappers.ValidationError: 1 validation error for Span
start
  start index must be non-negative (type=value_error)
[49]  2022-05-06 09:45:27.051 | ERROR    | sentry_sdk.integrations.logging:sentry_patched_callhandlers:86 - Failed to run labelling function
Traceback (most recent call last):

  File "programmatic/runner/run_functions.py", line 377, in programmatic.runner.run_functions.run_compiled_function_on_datapoint

  File "<string>", line 20, in mill
  File "<string>", line 20, in <listcomp>

  File "pydantic/main.py", line 331, in pydantic.main.BaseModel.__init__

pydantic.error_wrappers.ValidationError: 1 validation error for Span
start
  start index must be non-negative (type=value_error)
[49]  2022-05-06 09:45:27.060 | ERROR    | sentry_sdk.integrations.logging:sentry_patched_callhandlers:86 - Failed to run labelling function
Traceback (most recent call last):

  File "programmatic/runner/run_functions.py", line 377, in programmatic.runner.run_functions.run_compiled_function_on_datapoint

  File "<string>", line 20, in mill
  File "<string>", line 20, in <listcomp>

  File "pydantic/main.py", line 331, in pydantic.main.BaseModel.__init__

pydantic.error_wrappers.ValidationError: 1 validation error for Span
start
  start index must be non-negative (type=value_error)
[49]  2022-05-06 09:45:27.066 | ERROR    | sentry_sdk.integrations.logging:sentry_patched_callhandlers:86 - Failed to run labelling function
Traceback (most recent call last):

  File "programmatic/runner/run_functions.py", line 377, in programmatic.runner.run_functions.run_compiled_function_on_datapoint

  File "<string>", line 20, in mill
  File "<string>", line 20, in <listcomp>

  File "pydantic/main.py", line 331, in pydantic.main.BaseModel.__init__

pydantic.error_wrappers.ValidationError: 1 validation error for Span
start
  start index must be non-negative (type=value_error)
[49]  2022-05-06 09:45:27.073 | DEBUG    | sentry_sdk.integrations.logging:sentry_patched_callhandlers:86 - https://o427213.ingest.sentry.io:443 "POST /api/6142069/store/ HTTP/1.1" 200 41
[49]  2022-05-06 09:45:27.075 | ERROR    | sentry_sdk.integrations.logging:sentry_patched_callhandlers:86 - Failed to run labelling function
Traceback (most recent call last):

  File "programmatic/runner/run_functions.py", line 377, in programmatic.runner.run_functions.run_compiled_function_on_datapoint

  File "<string>", line 20, in mill
  File "<string>", line 20, in <listcomp>

  File "pydantic/main.py", line 331, in pydantic.main.BaseModel.__init__

pydantic.error_wrappers.ValidationError: 1 validation error for Span
start
  start index must be non-negative (type=value_error)
[49]  2022-05-06 09:45:27.095 | ERROR    | sentry_sdk.integrations.logging:sentry_patched_callhandlers:86 - Failed to run labelling function
Traceback (most recent call last):

  File "programmatic/runner/run_functions.py", line 377, in programmatic.runner.run_functions.run_compiled_function_on_datapoint

  File "<string>", line 20, in mill
  File "<string>", line 20, in <listcomp>

  File "pydantic/main.py", line 331, in pydantic.main.BaseModel.__init__

pydantic.error_wrappers.ValidationError: 1 validation error for Span
start
  start index must be non-negative (type=value_error)
[49]  2022-05-06 09:45:27.134 | DEBUG    | sentry_sdk.integrations.logging:sentry_patched_callhandlers:86 - https://o427213.ingest.sentry.io:443 "POST /api/6142069/store/ HTTP/1.1" 200 41
[49]  2022-05-06 09:45:27.181 | ERROR    | sentry_sdk.integrations.logging:sentry_patched_callhandlers:86 - Failed to run labelling function
Traceback (most recent call last):

  File "programmatic/runner/run_functions.py", line 377, in programmatic.runner.run_functions.run_compiled_function_on_datapoint

  File "<string>", line 20, in mill
  File "<string>", line 20, in <listcomp>

  File "pydantic/main.py", line 331, in pydantic.main.BaseModel.__init__

pydantic.error_wrappers.ValidationError: 1 validation error for Span
start
  start index must be non-negative (type=value_error)
[49]  2022-05-06 09:45:27.188 | DEBUG    | sentry_sdk.integrations.logging:sentry_patched_callhandlers:86 - https://o427213.ingest.sentry.io:443 "POST /api/6142069/store/ HTTP/1.1" 200 41
[49]  2022-05-06 09:45:27.229 | ERROR    | sentry_sdk.integrations.logging:sentry_patched_callhandlers:86 - Failed to run labelling function
Traceback (most recent call last):

  File "programmatic/runner/run_functions.py", line 377, in programmatic.runner.run_functions.run_compiled_function_on_datapoint

  File "<string>", line 20, in mill
  File "<string>", line 20, in <listcomp>

  File "pydantic/main.py", line 331, in pydantic.main.BaseModel.__init__

pydantic.error_wrappers.ValidationError: 1 validation error for Span
start
  start index must be non-negative (type=value_error)
[49]  2022-05-06 09:45:27.248 | ERROR    | sentry_sdk.integrations.logging:sentry_patched_callhandlers:86 - Failed to run labelling function
Traceback (most recent call last):

  File "programmatic/runner/run_functions.py", line 377, in programmatic.runner.run_functions.run_compiled_function_on_datapoint

  File "<string>", line 20, in mill
  File "<string>", line 20, in <listcomp>

  File "pydantic/main.py", line 331, in pydantic.main.BaseModel.__init__

pydantic.error_wrappers.ValidationError: 1 validation error for Span
start
  start index must be non-negative (type=value_error)
[49]  2022-05-06 09:45:27.255 | DEBUG    | sentry_sdk.integrations.logging:sentry_patched_callhandlers:86 - https://o427213.ingest.sentry.io:443 "POST /api/6142069/store/ HTTP/1.1" 200 41
[49]  2022-05-06 09:45:27.269 | ERROR    | sentry_sdk.integrations.logging:sentry_patched_callhandlers:86 - Failed to run labelling function
Traceback (most recent call last):

  File "programmatic/runner/run_functions.py", line 377, in programmatic.runner.run_functions.run_compiled_function_on_datapoint

  File "<string>", line 20, in mill
  File "<string>", line 20, in <listcomp>

  File "pydantic/main.py", line 331, in pydantic.main.BaseModel.__init__

pydantic.error_wrappers.ValidationError: 1 validation error for Span
start
  start index must be non-negative (type=value_error)
[49]  2022-05-06 09:45:27.277 | ERROR    | sentry_sdk.integrations.logging:sentry_patched_callhandlers:86 - Failed to run labelling function
Traceback (most recent call last):

  File "programmatic/runner/run_functions.py", line 377, in programmatic.runner.run_functions.run_compiled_function_on_datapoint

  File "<string>", line 20, in mill
  File "<string>", line 20, in <listcomp>

  File "pydantic/main.py", line 331, in pydantic.main.BaseModel.__init__

pydantic.error_wrappers.ValidationError: 1 validation error for Span
start
  start index must be non-negative (type=value_error)
[49]  2022-05-06 09:45:27.297 | DEBUG    | sentry_sdk.integrations.logging:sentry_patched_callhandlers:86 - https://o427213.ingest.sentry.io:443 "POST /api/6142069/store/ HTTP/1.1" 200 41
[49]  2022-05-06 09:45:27.329 | DEBUG    | sentry_sdk.integrations.logging:sentry_patched_callhandlers:86 - https://o427213.ingest.sentry.io:443 "POST /api/6142069/store/ HTTP/1.1" 200 41
[49]  2022-05-06 09:45:27.363 | DEBUG    | sentry_sdk.integrations.logging:sentry_patched_callhandlers:86 - https://o427213.ingest.sentry.io:443 "POST /api/6142069/store/ HTTP/1.1" 200 41
[49]  2022-05-06 09:45:27.423 | DEBUG    | sentry_sdk.integrations.logging:sentry_patched_callhandlers:86 - https://o427213.ingest.sentry.io:443 "POST /api/6142069/store/ HTTP/1.1" 200 41
[47]  2022-05-06 09:45:27.472 | ERROR    | sentry_sdk.integrations.logging:sentry_patched_callhandlers:86 - Failed to run labelling function
Traceback (most recent call last):

  File "programmatic/runner/run_functions.py", line 377, in programmatic.runner.run_functions.run_compiled_function_on_datapoint

  File "<string>", line 20, in mill
  File "<string>", line 20, in <listcomp>

  File "pydantic/main.py", line 331, in pydantic.main.BaseModel.__init__

pydantic.error_wrappers.ValidationError: 1 validation error for Span
start
  start index must be non-negative (type=value_error)
[49]  2022-05-06 09:45:27.477 | DEBUG    | sentry_sdk.integrations.logging:sentry_patched_callhandlers:86 - https://o427213.ingest.sentry.io:443 "POST /api/6142069/store/ HTTP/1.1" 200 41
[49]  2022-05-06 09:45:27.514 | ERROR    | sentry_sdk.integrations.logging:sentry_patched_callhandlers:86 - Failed to run labelling function
Traceback (most recent call last):

  File "programmatic/runner/run_functions.py", line 377, in programmatic.runner.run_functions.run_compiled_function_on_datapoint

  File "<string>", line 20, in mill
  File "<string>", line 20, in <listcomp>

  File "pydantic/main.py", line 331, in pydantic.main.BaseModel.__init__

pydantic.error_wrappers.ValidationError: 1 validation error for Span
start
  start index must be non-negative (type=value_error)
[49]  2022-05-06 09:45:27.543 | ERROR    | sentry_sdk.integrations.logging:sentry_patched_callhandlers:86 - Failed to run labelling function
Traceback (most recent call last):

  File "programmatic/runner/run_functions.py", line 377, in programmatic.runner.run_functions.run_compiled_function_on_datapoint

  File "<string>", line 20, in mill
  File "<string>", line 20, in <listcomp>

  File "pydantic/main.py", line 331, in pydantic.main.BaseModel.__init__

pydantic.error_wrappers.ValidationError: 1 validation error for Span
start
  start index must be non-negative (type=value_error)
[49]  2022-05-06 09:45:27.545 | DEBUG    | sentry_sdk.integrations.logging:sentry_patched_callhandlers:86 - https://o427213.ingest.sentry.io:443 "POST /api/6142069/store/ HTTP/1.1" 200 41
[47]  2022-05-06 09:45:27.551 | DEBUG    | sentry_sdk.integrations.logging:sentry_patched_callhandlers:86 - Starting new HTTPS connection (1): o427213.ingest.sentry.io:443
[49]  2022-05-06 09:45:27.569 | ERROR    | sentry_sdk.integrations.logging:sentry_patched_callhandlers:86 - Failed to run labelling function
Traceback (most recent call last):

  File "programmatic/runner/run_functions.py", line 377, in programmatic.runner.run_functions.run_compiled_function_on_datapoint

  File "<string>", line 20, in mill
  File "<string>", line 20, in <listcomp>

  File "pydantic/main.py", line 331, in pydantic.main.BaseModel.__init__

pydantic.error_wrappers.ValidationError: 1 validation error for Span
start
  start index must be non-negative (type=value_error)
[49]  2022-05-06 09:45:27.576 | ERROR    | sentry_sdk.integrations.logging:sentry_patched_callhandlers:86 - Failed to run labelling function
Traceback (most recent call last):

  File "programmatic/runner/run_functions.py", line 377, in programmatic.runner.run_functions.run_compiled_function_on_datapoint

  File "<string>", line 20, in mill
  File "<string>", line 20, in <listcomp>

  File "pydantic/main.py", line 331, in pydantic.main.BaseModel.__init__

pydantic.error_wrappers.ValidationError: 1 validation error for Span
start
  start index must be non-negative (type=value_error)
[49]  2022-05-06 09:45:27.585 | ERROR    | sentry_sdk.integrations.logging:sentry_patched_callhandlers:86 - Failed to run labelling function
Traceback (most recent call last):

  File "programmatic/runner/run_functions.py", line 377, in programmatic.runner.run_functions.run_compiled_function_on_datapoint

  File "<string>", line 20, in mill
  File "<string>", line 20, in <listcomp>

  File "pydantic/main.py", line 331, in pydantic.main.BaseModel.__init__

pydantic.error_wrappers.ValidationError: 1 validation error for Span
start
  start index must be non-negative (type=value_error)
[49]  2022-05-06 09:45:27.592 | ERROR    | sentry_sdk.integrations.logging:sentry_patched_callhandlers:86 - Failed to run labelling function
Traceback (most recent call last):

  File "programmatic/runner/run_functions.py", line 377, in programmatic.runner.run_functions.run_compiled_function_on_datapoint

  File "<string>", line 20, in mill
  File "<string>", line 20, in <listcomp>

  File "pydantic/main.py", line 331, in pydantic.main.BaseModel.__init__

pydantic.error_wrappers.ValidationError: 1 validation error for Span
start
  start index must be non-negative (type=value_error)
[49]  2022-05-06 09:45:27.602 | ERROR    | sentry_sdk.integrations.logging:sentry_patched_callhandlers:86 - Failed to run labelling function
Traceback (most recent call last):

  File "programmatic/runner/run_functions.py", line 377, in programmatic.runner.run_functions.run_compiled_function_on_datapoint

  File "<string>", line 20, in mill
  File "<string>", line 20, in <listcomp>

  File "pydantic/main.py", line 331, in pydantic.main.BaseModel.__init__

pydantic.error_wrappers.ValidationError: 1 validation error for Span
start
  start index must be non-negative (type=value_error)
[49]  2022-05-06 09:45:27.608 | DEBUG    | sentry_sdk.integrations.logging:sentry_patched_callhandlers:86 - https://o427213.ingest.sentry.io:443 "POST /api/6142069/store/ HTTP/1.1" 200 41
[49]  2022-05-06 09:45:27.622 | ERROR    | sentry_sdk.integrations.logging:sentry_patched_callhandlers:86 - Failed to run labelling function
Traceback (most recent call last):

  File "programmatic/runner/run_functions.py", line 377, in programmatic.runner.run_functions.run_compiled_function_on_datapoint

  File "<string>", line 20, in mill
  File "<string>", line 20, in <listcomp>

  File "pydantic/main.py", line 331, in pydantic.main.BaseModel.__init__

pydantic.error_wrappers.ValidationError: 1 validation error for Span
start
  start index must be non-negative (type=value_error)
[47]  2022-05-06 09:45:27.644 | DEBUG    | sentry_sdk.integrations.logging:sentry_patched_callhandlers:86 - https://o427213.ingest.sentry.io:443 "POST /api/6142069/store/ HTTP/1.1" 200 41
[49]  2022-05-06 09:45:27.641 | ERROR    | sentry_sdk.integrations.logging:sentry_patched_callhandlers:86 - Failed to run labelling function
Traceback (most recent call last):

  File "programmatic/runner/run_functions.py", line 377, in programmatic.runner.run_functions.run_compiled_function_on_datapoint

  File "<string>", line 20, in mill
  File "<string>", line 20, in <listcomp>

  File "pydantic/main.py", line 331, in pydantic.main.BaseModel.__init__

pydantic.error_wrappers.ValidationError: 1 validation error for Span
start
  start index must be non-negative (type=value_error)
[49]  2022-05-06 09:45:27.650 | DEBUG    | sentry_sdk.integrations.logging:sentry_patched_callhandlers:86 - https://o427213.ingest.sentry.io:443 "POST /api/6142069/store/ HTTP/1.1" 200 41
[49]  2022-05-06 09:45:27.661 | ERROR    | sentry_sdk.integrations.logging:sentry_patched_callhandlers:86 - Failed to run labelling function
Traceback (most recent call last):

  File "programmatic/runner/run_functions.py", line 377, in programmatic.runner.run_functions.run_compiled_function_on_datapoint

  File "<string>", line 20, in mill
  File "<string>", line 20, in <listcomp>

  File "pydantic/main.py", line 331, in pydantic.main.BaseModel.__init__

pydantic.error_wrappers.ValidationError: 1 validation error for Span
start
  start index must be non-negative (type=value_error)
[49]  2022-05-06 09:45:27.685 | ERROR    | sentry_sdk.integrations.logging:sentry_patched_callhandlers:86 - Failed to run labelling function
Traceback (most recent call last):

  File "programmatic/runner/run_functions.py", line 377, in programmatic.runner.run_functions.run_compiled_function_on_datapoint

  File "<string>", line 20, in mill
  File "<string>", line 20, in <listcomp>

  File "pydantic/main.py", line 331, in pydantic.main.BaseModel.__init__

pydantic.error_wrappers.ValidationError: 1 validation error for Span
start
  start index must be non-negative (type=value_error)
[49]  2022-05-06 09:45:27.694 | ERROR    | sentry_sdk.integrations.logging:sentry_patched_callhandlers:86 - Failed to run labelling function
Traceback (most recent call last):

  File "programmatic/runner/run_functions.py", line 377, in programmatic.runner.run_functions.run_compiled_function_on_datapoint

  File "<string>", line 20, in mill
  File "<string>", line 20, in <listcomp>

  File "pydantic/main.py", line 331, in pydantic.main.BaseModel.__init__

pydantic.error_wrappers.ValidationError: 1 validation error for Span
start
  start index must be non-negative (type=value_error)
[49]  2022-05-06 09:45:27.708 | DEBUG    | sentry_sdk.integrations.logging:sentry_patched_callhandlers:86 - https://o427213.ingest.sentry.io:443 "POST /api/6142069/store/ HTTP/1.1" 200 41
[49]  2022-05-06 09:45:27.750 | ERROR    | sentry_sdk.integrations.logging:sentry_patched_callhandlers:86 - Failed to run labelling function
Traceback (most recent call last):

  File "programmatic/runner/run_functions.py", line 377, in programmatic.runner.run_functions.run_compiled_function_on_datapoint

  File "<string>", line 20, in mill
  File "<string>", line 20, in <listcomp>

  File "pydantic/main.py", line 331, in pydantic.main.BaseModel.__init__

pydantic.error_wrappers.ValidationError: 1 validation error for Span
start
  start index must be non-negative (type=value_error)
[49]  2022-05-06 09:45:27.899 | DEBUG    | sentry_sdk.integrations.logging:sentry_patched_callhandlers:86 - https://o427213.ingest.sentry.io:443 "POST /api/6142069/store/ HTTP/1.1" 200 41
[49]  2022-05-06 09:45:27.956 | DEBUG    | sentry_sdk.integrations.logging:sentry_patched_callhandlers:86 - https://o427213.ingest.sentry.io:443 "POST /api/6142069/store/ HTTP/1.1" 200 41
[49]  2022-05-06 09:45:27.976 | ERROR    | sentry_sdk.integrations.logging:sentry_patched_callhandlers:86 - Failed to run labelling function
Traceback (most recent call last):

  File "programmatic/runner/run_functions.py", line 377, in programmatic.runner.run_functions.run_compiled_function_on_datapoint

  File "<string>", line 20, in mill
  File "<string>", line 20, in <listcomp>

  File "pydantic/main.py", line 331, in pydantic.main.BaseModel.__init__

pydantic.error_wrappers.ValidationError: 1 validation error for Span
start
  start index must be non-negative (type=value_error)
[49]  2022-05-06 09:45:27.999 | DEBUG    | sentry_sdk.integrations.logging:sentry_patched_callhandlers:86 - https://o427213.ingest.sentry.io:443 "POST /api/6142069/store/ HTTP/1.1" 200 41
[49]  2022-05-06 09:45:28.029 | ERROR    | sentry_sdk.integrations.logging:sentry_patched_callhandlers:86 - Failed to run labelling function
Traceback (most recent call last):

  File "programmatic/runner/run_functions.py", line 377, in programmatic.runner.run_functions.run_compiled_function_on_datapoint

  File "<string>", line 20, in mill
  File "<string>", line 20, in <listcomp>

  File "pydantic/main.py", line 331, in pydantic.main.BaseModel.__init__

pydantic.error_wrappers.ValidationError: 1 validation error for Span
start
  start index must be non-negative (type=value_error)
[49]  2022-05-06 09:45:28.041 | ERROR    | sentry_sdk.integrations.logging:sentry_patched_callhandlers:86 - Failed to run labelling function
Traceback (most recent call last):

  File "programmatic/runner/run_functions.py", line 377, in programmatic.runner.run_functions.run_compiled_function_on_datapoint

  File "<string>", line 20, in mill
  File "<string>", line 20, in <listcomp>

  File "pydantic/main.py", line 331, in pydantic.main.BaseModel.__init__

pydantic.error_wrappers.ValidationError: 1 validation error for Span
start
  start index must be non-negative (type=value_error)
[49]  2022-05-06 09:45:28.055 | DEBUG    | sentry_sdk.integrations.logging:sentry_patched_callhandlers:86 - https://o427213.ingest.sentry.io:443 "POST /api/6142069/store/ HTTP/1.1" 200 41
[49]  2022-05-06 09:45:28.058 | ERROR    | sentry_sdk.integrations.logging:sentry_patched_callhandlers:86 - Failed to run labelling function
Traceback (most recent call last):

  File "programmatic/runner/run_functions.py", line 377, in programmatic.runner.run_functions.run_compiled_function_on_datapoint

  File "<string>", line 20, in mill
  File "<string>", line 20, in <listcomp>

  File "pydantic/main.py", line 331, in pydantic.main.BaseModel.__init__

pydantic.error_wrappers.ValidationError: 1 validation error for Span
start
  start index must be non-negative (type=value_error)
[49]  2022-05-06 09:45:28.068 | ERROR    | sentry_sdk.integrations.logging:sentry_patched_callhandlers:86 - Failed to run labelling function
Traceback (most recent call last):

  File "programmatic/runner/run_functions.py", line 377, in programmatic.runner.run_functions.run_compiled_function_on_datapoint

  File "<string>", line 20, in mill
  File "<string>", line 20, in <listcomp>

  File "pydantic/main.py", line 331, in pydantic.main.BaseModel.__init__

pydantic.error_wrappers.ValidationError: 1 validation error for Span
start
  start index must be non-negative (type=value_error)
[49]  2022-05-06 09:45:28.079 | ERROR    | sentry_sdk.integrations.logging:sentry_patched_callhandlers:86 - Failed to run labelling function
Traceback (most recent call last):

  File "programmatic/runner/run_functions.py", line 377, in programmatic.runner.run_functions.run_compiled_function_on_datapoint

  File "<string>", line 20, in mill
  File "<string>", line 20, in <listcomp>

  File "pydantic/main.py", line 331, in pydantic.main.BaseModel.__init__

pydantic.error_wrappers.ValidationError: 1 validation error for Span
start
  start index must be non-negative (type=value_error)
[49]  2022-05-06 09:45:28.089 | ERROR    | sentry_sdk.integrations.logging:sentry_patched_callhandlers:86 - Failed to run labelling function
Traceback (most recent call last):

  File "programmatic/runner/run_functions.py", line 377, in programmatic.runner.run_functions.run_compiled_function_on_datapoint

  File "<string>", line 20, in mill
  File "<string>", line 20, in <listcomp>

  File "pydantic/main.py", line 331, in pydantic.main.BaseModel.__init__

pydantic.error_wrappers.ValidationError: 1 validation error for Span
start
  start index must be non-negative (type=value_error)
[49]  2022-05-06 09:45:28.096 | DEBUG    | sentry_sdk.integrations.logging:sentry_patched_callhandlers:86 - https://o427213.ingest.sentry.io:443 "POST /api/6142069/store/ HTTP/1.1" 200 41
[49]  2022-05-06 09:45:28.099 | ERROR    | sentry_sdk.integrations.logging:sentry_patched_callhandlers:86 - Failed to run labelling function
Traceback (most recent call last):

  File "programmatic/runner/run_functions.py", line 377, in programmatic.runner.run_functions.run_compiled_function_on_datapoint

  File "<string>", line 20, in mill
  File "<string>", line 20, in <listcomp>

  File "pydantic/main.py", line 331, in pydantic.main.BaseModel.__init__

pydantic.error_wrappers.ValidationError: 1 validation error for Span
start
  start index must be non-negative (type=value_error)
[49]  2022-05-06 09:45:28.112 | ERROR    | sentry_sdk.integrations.logging:sentry_patched_callhandlers:86 - Failed to run labelling function
Traceback (most recent call last):

  File "programmatic/runner/run_functions.py", line 377, in programmatic.runner.run_functions.run_compiled_function_on_datapoint

  File "<string>", line 20, in mill
  File "<string>", line 20, in <listcomp>

  File "pydantic/main.py", line 331, in pydantic.main.BaseModel.__init__

pydantic.error_wrappers.ValidationError: 1 validation error for Span
start
  start index must be non-negative (type=value_error)
[49]  2022-05-06 09:45:28.121 | ERROR    | sentry_sdk.integrations.logging:sentry_patched_callhandlers:86 - Failed to run labelling function
Traceback (most recent call last):

  File "programmatic/runner/run_functions.py", line 377, in programmatic.runner.run_functions.run_compiled_function_on_datapoint

  File "<string>", line 20, in mill
  File "<string>", line 20, in <listcomp>

  File "pydantic/main.py", line 331, in pydantic.main.BaseModel.__init__

pydantic.error_wrappers.ValidationError: 1 validation error for Span
start
  start index must be non-negative (type=value_error)
[49]  2022-05-06 09:45:28.130 | ERROR    | sentry_sdk.integrations.logging:sentry_patched_callhandlers:86 - Failed to run labelling function
Traceback (most recent call last):

  File "programmatic/runner/run_functions.py", line 377, in programmatic.runner.run_functions.run_compiled_function_on_datapoint

  File "<string>", line 20, in mill
  File "<string>", line 20, in <listcomp>

  File "pydantic/main.py", line 331, in pydantic.main.BaseModel.__init__

pydantic.error_wrappers.ValidationError: 1 validation error for Span
start
  start index must be non-negative (type=value_error)
[49]  2022-05-06 09:45:28.214 | ERROR    | sentry_sdk.integrations.logging:sentry_patched_callhandlers:86 - Failed to run labelling function
Traceback (most recent call last):

  File "programmatic/runner/run_functions.py", line 377, in programmatic.runner.run_functions.run_compiled_function_on_datapoint

  File "<string>", line 20, in mill
  File "<string>", line 20, in <listcomp>

  File "pydantic/main.py", line 331, in pydantic.main.BaseModel.__init__

pydantic.error_wrappers.ValidationError: 1 validation error for Span
start
  start index must be non-negative (type=value_error)
[49]  2022-05-06 09:45:28.222 | ERROR    | sentry_sdk.integrations.logging:sentry_patched_callhandlers:86 - Failed to run labelling function
Traceback (most recent call last):

  File "programmatic/runner/run_functions.py", line 377, in programmatic.runner.run_functions.run_compiled_function_on_datapoint

  File "<string>", line 20, in mill
  File "<string>", line 20, in <listcomp>

  File "pydantic/main.py", line 331, in pydantic.main.BaseModel.__init__

pydantic.error_wrappers.ValidationError: 1 validation error for Span
start
  start index must be non-negative (type=value_error)
[49]  2022-05-06 09:45:28.230 | ERROR    | sentry_sdk.integrations.logging:sentry_patched_callhandlers:86 - Failed to run labelling function
Traceback (most recent call last):

  File "programmatic/runner/run_functions.py", line 377, in programmatic.runner.run_functions.run_compiled_function_on_datapoint

  File "<string>", line 20, in mill
  File "<string>", line 20, in <listcomp>

  File "pydantic/main.py", line 331, in pydantic.main.BaseModel.__init__

pydantic.error_wrappers.ValidationError: 1 validation error for Span
start
  start index must be non-negative (type=value_error)
[49]  2022-05-06 09:45:28.238 | ERROR    | sentry_sdk.integrations.logging:sentry_patched_callhandlers:86 - Failed to run labelling function
Traceback (most recent call last):

  File "programmatic/runner/run_functions.py", line 377, in programmatic.runner.run_functions.run_compiled_function_on_datapoint

  File "<string>", line 20, in mill
  File "<string>", line 20, in <listcomp>

  File "pydantic/main.py", line 331, in pydantic.main.BaseModel.__init__

pydantic.error_wrappers.ValidationError: 1 validation error for Span
start
  start index must be non-negative (type=value_error)
[49]  2022-05-06 09:45:28.338 | ERROR    | sentry_sdk.integrations.logging:sentry_patched_callhandlers:86 - Failed to run labelling function
Traceback (most recent call last):

  File "programmatic/runner/run_functions.py", line 377, in programmatic.runner.run_functions.run_compiled_function_on_datapoint

  File "<string>", line 20, in mill
  File "<string>", line 20, in <listcomp>

  File "pydantic/main.py", line 331, in pydantic.main.BaseModel.__init__

pydantic.error_wrappers.ValidationError: 1 validation error for Span
start
  start index must be non-negative (type=value_error)
[49]  2022-05-06 09:45:28.361 | ERROR    | sentry_sdk.integrations.logging:sentry_patched_callhandlers:86 - Failed to run labelling function
Traceback (most recent call last):

  File "programmatic/runner/run_functions.py", line 377, in programmatic.runner.run_functions.run_compiled_function_on_datapoint

  File "<string>", line 20, in mill
  File "<string>", line 20, in <listcomp>

  File "pydantic/main.py", line 331, in pydantic.main.BaseModel.__init__

pydantic.error_wrappers.ValidationError: 1 validation error for Span
start
  start index must be non-negative (type=value_error)
[49]  2022-05-06 09:45:28.369 | ERROR    | sentry_sdk.integrations.logging:sentry_patched_callhandlers:86 - Failed to run labelling function
Traceback (most recent call last):

  File "programmatic/runner/run_functions.py", line 377, in programmatic.runner.run_functions.run_compiled_function_on_datapoint

  File "<string>", line 20, in mill
  File "<string>", line 20, in <listcomp>

  File "pydantic/main.py", line 331, in pydantic.main.BaseModel.__init__

pydantic.error_wrappers.ValidationError: 1 validation error for Span
start
  start index must be non-negative (type=value_error)
[49]  2022-05-06 09:45:28.453 | ERROR    | sentry_sdk.integrations.logging:sentry_patched_callhandlers:86 - Failed to run labelling function
Traceback (most recent call last):

  File "programmatic/runner/run_functions.py", line 377, in programmatic.runner.run_functions.run_compiled_function_on_datapoint

  File "<string>", line 20, in mill
  File "<string>", line 20, in <listcomp>

  File "pydantic/main.py", line 331, in pydantic.main.BaseModel.__init__

pydantic.error_wrappers.ValidationError: 1 validation error for Span
start
  start index must be non-negative (type=value_error)
[49]  2022-05-06 09:45:28.460 | ERROR    | sentry_sdk.integrations.logging:sentry_patched_callhandlers:86 - Failed to run labelling function
Traceback (most recent call last):

  File "programmatic/runner/run_functions.py", line 377, in programmatic.runner.run_functions.run_compiled_function_on_datapoint

  File "<string>", line 20, in mill
  File "<string>", line 20, in <listcomp>

  File "pydantic/main.py", line 331, in pydantic.main.BaseModel.__init__

pydantic.error_wrappers.ValidationError: 1 validation error for Span
start
  start index must be non-negative (type=value_error)
[49]  2022-05-06 09:45:28.468 | ERROR    | sentry_sdk.integrations.logging:sentry_patched_callhandlers:86 - Failed to run labelling function
Traceback (most recent call last):

  File "programmatic/runner/run_functions.py", line 377, in programmatic.runner.run_functions.run_compiled_function_on_datapoint

  File "<string>", line 20, in mill
  File "<string>", line 20, in <listcomp>

  File "pydantic/main.py", line 331, in pydantic.main.BaseModel.__init__

pydantic.error_wrappers.ValidationError: 1 validation error for Span
start
  start index must be non-negative (type=value_error)
[49]  2022-05-06 09:45:28.484 | ERROR    | sentry_sdk.integrations.logging:sentry_patched_callhandlers:86 - Failed to run labelling function
Traceback (most recent call last):

  File "programmatic/runner/run_functions.py", line 377, in programmatic.runner.run_functions.run_compiled_function_on_datapoint

  File "<string>", line 20, in mill
  File "<string>", line 20, in <listcomp>

  File "pydantic/main.py", line 331, in pydantic.main.BaseModel.__init__

pydantic.error_wrappers.ValidationError: 1 validation error for Span
start
  start index must be non-negative (type=value_error)
[49]  2022-05-06 09:45:28.491 | ERROR    | sentry_sdk.integrations.logging:sentry_patched_callhandlers:86 - Failed to run labelling function
Traceback (most recent call last):

  File "programmatic/runner/run_functions.py", line 377, in programmatic.runner.run_functions.run_compiled_function_on_datapoint

  File "<string>", line 20, in mill
  File "<string>", line 20, in <listcomp>

  File "pydantic/main.py", line 331, in pydantic.main.BaseModel.__init__

pydantic.error_wrappers.ValidationError: 1 validation error for Span
start
  start index must be non-negative (type=value_error)
[49]  2022-05-06 09:45:28.500 | ERROR    | sentry_sdk.integrations.logging:sentry_patched_callhandlers:86 - Failed to run labelling function
Traceback (most recent call last):

  File "programmatic/runner/run_functions.py", line 377, in programmatic.runner.run_functions.run_compiled_function_on_datapoint

  File "<string>", line 20, in mill
  File "<string>", line 20, in <listcomp>

  File "pydantic/main.py", line 331, in pydantic.main.BaseModel.__init__

pydantic.error_wrappers.ValidationError: 1 validation error for Span
start
  start index must be non-negative (type=value_error)
[49]  2022-05-06 09:45:28.508 | ERROR    | sentry_sdk.integrations.logging:sentry_patched_callhandlers:86 - Failed to run labelling function
Traceback (most recent call last):

  File "programmatic/runner/run_functions.py", line 377, in programmatic.runner.run_functions.run_compiled_function_on_datapoint

  File "<string>", line 20, in mill
  File "<string>", line 20, in <listcomp>

  File "pydantic/main.py", line 331, in pydantic.main.BaseModel.__init__

pydantic.error_wrappers.ValidationError: 1 validation error for Span
start
  start index must be non-negative (type=value_error)
[49]  2022-05-06 09:45:28.515 | ERROR    | sentry_sdk.integrations.logging:sentry_patched_callhandlers:86 - Failed to run labelling function
Traceback (most recent call last):

  File "programmatic/runner/run_functions.py", line 377, in programmatic.runner.run_functions.run_compiled_function_on_datapoint

  File "<string>", line 20, in mill
  File "<string>", line 20, in <listcomp>

  File "pydantic/main.py", line 331, in pydantic.main.BaseModel.__init__

pydantic.error_wrappers.ValidationError: 1 validation error for Span
start
  start index must be non-negative (type=value_error)
[49]  2022-05-06 09:45:28.523 | ERROR    | sentry_sdk.integrations.logging:sentry_patched_callhandlers:86 - Failed to run labelling function
Traceback (most recent call last):

  File "programmatic/runner/run_functions.py", line 377, in programmatic.runner.run_functions.run_compiled_function_on_datapoint

  File "<string>", line 20, in mill
  File "<string>", line 20, in <listcomp>

  File "pydantic/main.py", line 331, in pydantic.main.BaseModel.__init__

pydantic.error_wrappers.ValidationError: 1 validation error for Span
start
  start index must be non-negative (type=value_error)
[49]  2022-05-06 09:45:28.698 | ERROR    | sentry_sdk.integrations.logging:sentry_patched_callhandlers:86 - Failed to run labelling function
Traceback (most recent call last):

  File "programmatic/runner/run_functions.py", line 377, in programmatic.runner.run_functions.run_compiled_function_on_datapoint

  File "<string>", line 20, in mill
  File "<string>", line 20, in <listcomp>

  File "pydantic/main.py", line 331, in pydantic.main.BaseModel.__init__

pydantic.error_wrappers.ValidationError: 1 validation error for Span
start
  start index must be non-negative (type=value_error)
[49]  2022-05-06 09:45:28.705 | ERROR    | sentry_sdk.integrations.logging:sentry_patched_callhandlers:86 - Failed to run labelling function
Traceback (most recent call last):

  File "programmatic/runner/run_functions.py", line 377, in programmatic.runner.run_functions.run_compiled_function_on_datapoint

  File "<string>", line 20, in mill
  File "<string>", line 20, in <listcomp>

  File "pydantic/main.py", line 331, in pydantic.main.BaseModel.__init__

pydantic.error_wrappers.ValidationError: 1 validation error for Span
start
  start index must be non-negative (type=value_error)
[49]  2022-05-06 09:45:28.713 | ERROR    | sentry_sdk.integrations.logging:sentry_patched_callhandlers:86 - Failed to run labelling function
Traceback (most recent call last):

  File "programmatic/runner/run_functions.py", line 377, in programmatic.runner.run_functions.run_compiled_function_on_datapoint

  File "<string>", line 20, in mill
  File "<string>", line 20, in <listcomp>

  File "pydantic/main.py", line 331, in pydantic.main.BaseModel.__init__

pydantic.error_wrappers.ValidationError: 1 validation error for Span
start
  start index must be non-negative (type=value_error)
[49]  2022-05-06 09:45:28.720 | ERROR    | sentry_sdk.integrations.logging:sentry_patched_callhandlers:86 - Failed to run labelling function
Traceback (most recent call last):

  File "programmatic/runner/run_functions.py", line 377, in programmatic.runner.run_functions.run_compiled_function_on_datapoint

  File "<string>", line 20, in mill
  File "<string>", line 20, in <listcomp>

  File "pydantic/main.py", line 331, in pydantic.main.BaseModel.__init__

pydantic.error_wrappers.ValidationError: 1 validation error for Span
start
  start index must be non-negative (type=value_error)
[49]  2022-05-06 09:45:28.728 | ERROR    | sentry_sdk.integrations.logging:sentry_patched_callhandlers:86 - Failed to run labelling function
Traceback (most recent call last):

  File "programmatic/runner/run_functions.py", line 377, in programmatic.runner.run_functions.run_compiled_function_on_datapoint

  File "<string>", line 20, in mill
  File "<string>", line 20, in <listcomp>

  File "pydantic/main.py", line 331, in pydantic.main.BaseModel.__init__

pydantic.error_wrappers.ValidationError: 1 validation error for Span
start
  start index must be non-negative (type=value_error)
[49]  2022-05-06 09:45:28.741 | ERROR    | sentry_sdk.integrations.logging:sentry_patched_callhandlers:86 - Failed to run labelling function
Traceback (most recent call last):

  File "programmatic/runner/run_functions.py", line 377, in programmatic.runner.run_functions.run_compiled_function_on_datapoint

  File "<string>", line 20, in mill
  File "<string>", line 20, in <listcomp>

  File "pydantic/main.py", line 331, in pydantic.main.BaseModel.__init__

pydantic.error_wrappers.ValidationError: 1 validation error for Span
start
  start index must be non-negative (type=value_error)
[49]  2022-05-06 09:45:28.872 | ERROR    | sentry_sdk.integrations.logging:sentry_patched_callhandlers:86 - Failed to run labelling function
Traceback (most recent call last):

  File "programmatic/runner/run_functions.py", line 377, in programmatic.runner.run_functions.run_compiled_function_on_datapoint

  File "<string>", line 20, in mill
  File "<string>", line 20, in <listcomp>

  File "pydantic/main.py", line 331, in pydantic.main.BaseModel.__init__

pydantic.error_wrappers.ValidationError: 1 validation error for Span
start
  start index must be non-negative (type=value_error)
[49]  2022-05-06 09:45:28.879 | ERROR    | sentry_sdk.integrations.logging:sentry_patched_callhandlers:86 - Failed to run labelling function
Traceback (most recent call last):

  File "programmatic/runner/run_functions.py", line 377, in programmatic.runner.run_functions.run_compiled_function_on_datapoint

  File "<string>", line 20, in mill
  File "<string>", line 20, in <listcomp>

  File "pydantic/main.py", line 331, in pydantic.main.BaseModel.__init__

pydantic.error_wrappers.ValidationError: 1 validation error for Span
start
  start index must be non-negative (type=value_error)
[49]  2022-05-06 09:45:28.885 | ERROR    | sentry_sdk.integrations.logging:sentry_patched_callhandlers:86 - Failed to run labelling function
Traceback (most recent call last):

  File "programmatic/runner/run_functions.py", line 377, in programmatic.runner.run_functions.run_compiled_function_on_datapoint

  File "<string>", line 20, in mill
  File "<string>", line 20, in <listcomp>

  File "pydantic/main.py", line 331, in pydantic.main.BaseModel.__init__

pydantic.error_wrappers.ValidationError: 1 validation error for Span
start
  start index must be non-negative (type=value_error)
[49]  2022-05-06 09:45:28.893 | ERROR    | sentry_sdk.integrations.logging:sentry_patched_callhandlers:86 - Failed to run labelling function
Traceback (most recent call last):

  File "programmatic/runner/run_functions.py", line 377, in programmatic.runner.run_functions.run_compiled_function_on_datapoint

  File "<string>", line 20, in mill
  File "<string>", line 20, in <listcomp>

  File "pydantic/main.py", line 331, in pydantic.main.BaseModel.__init__

pydantic.error_wrappers.ValidationError: 1 validation error for Span
start
  start index must be non-negative (type=value_error)
[49]  2022-05-06 09:45:28.958 | WARNING  | sentry_sdk.integrations.logging:sentry_patched_callhandlers:86 - Run run_k6tlMtqV_5Q-ZwvRcHnAG for labelling function mill failed with 116 failures out of 94088 data points.
[49]  2022-05-06 09:45:32.475 | DEBUG    | sentry_sdk.integrations.logging:sentry_patched_callhandlers:86 - https://o427213.ingest.sentry.io:443 "POST /api/6142069/store/ HTTP/1.1" 200 41
[49]  2022-05-06 09:45:32.502 | DEBUG    | sentry_sdk.integrations.logging:sentry_patched_callhandlers:86 - https://o427213.ingest.sentry.io:443 "POST /api/6142069/store/ HTTP/1.1" 200 41
[49]  2022-05-06 09:45:32.530 | DEBUG    | sentry_sdk.integrations.logging:sentry_patched_callhandlers:86 - https://o427213.ingest.sentry.io:443 "POST /api/6142069/store/ HTTP/1.1" 200 41
[49]  2022-05-06 09:45:32.558 | DEBUG    | sentry_sdk.integrations.logging:sentry_patched_callhandlers:86 - https://o427213.ingest.sentry.io:443 "POST /api/6142069/store/ HTTP/1.1" 200 41
[49]  2022-05-06 09:45:32.585 | DEBUG    | sentry_sdk.integrations.logging:sentry_patched_callhandlers:86 - https://o427213.ingest.sentry.io:443 "POST /api/6142069/store/ HTTP/1.1" 200 41
[49]  2022-05-06 09:45:34.776 | DEBUG    | sentry_sdk.integrations.logging:sentry_patched_callhandlers:86 - https://o427213.ingest.sentry.io:443 "POST /api/6142069/store/ HTTP/1.1" 200 41
[49]  2022-05-06 09:45:34.809 | DEBUG    | sentry_sdk.integrations.logging:sentry_patched_callhandlers:86 - https://o427213.ingest.sentry.io:443 "POST /api/6142069/store/ HTTP/1.1" 200 41
[49]  2022-05-06 09:45:34.835 | DEBUG    | sentry_sdk.integrations.logging:sentry_patched_callhandlers:86 - https://o427213.ingest.sentry.io:443 "POST /api/6142069/store/ HTTP/1.1" 200 41
[49]  2022-05-06 09:45:34.866 | DEBUG    | sentry_sdk.integrations.logging:sentry_patched_callhandlers:86 - https://o427213.ingest.sentry.io:443 "POST /api/6142069/store/ HTTP/1.1" 200 41
[49]  2022-05-06 09:45:34.895 | DEBUG    | sentry_sdk.integrations.logging:sentry_patched_callhandlers:86 - https://o427213.ingest.sentry.io:443 "POST /api/6142069/store/ HTTP/1.1" 200 41
[49]  2022-05-06 09:45:34.924 | DEBUG    | sentry_sdk.integrations.logging:sentry_patched_callhandlers:86 - https://o427213.ingest.sentry.io:443 "POST /api/6142069/store/ HTTP/1.1" 200 41
[49]  2022-05-06 09:45:34.953 | DEBUG    | sentry_sdk.integrations.logging:sentry_patched_callhandlers:86 - https://o427213.ingest.sentry.io:443 "POST /api/6142069/store/ HTTP/1.1" 200 41
[49]  2022-05-06 09:45:34.986 | DEBUG    | sentry_sdk.integrations.logging:sentry_patched_callhandlers:86 - https://o427213.ingest.sentry.io:443 "POST /api/6142069/store/ HTTP/1.1" 200 41
[49]  2022-05-06 09:45:35.018 | DEBUG    | sentry_sdk.integrations.logging:sentry_patched_callhandlers:86 - https://o427213.ingest.sentry.io:443 "POST /api/6142069/store/ HTTP/1.1" 200 41
[49]  2022-05-06 09:45:35.049 | DEBUG    | sentry_sdk.integrations.logging:sentry_patched_callhandlers:86 - https://o427213.ingest.sentry.io:443 "POST /api/6142069/store/ HTTP/1.1" 200 41
[49]  2022-05-06 09:45:35.079 | DEBUG    | sentry_sdk.integrations.logging:sentry_patched_callhandlers:86 - https://o427213.ingest.sentry.io:443 "POST /api/6142069/store/ HTTP/1.1" 200 41
[49]  2022-05-06 09:45:35.109 | DEBUG    | sentry_sdk.integrations.logging:sentry_patched_callhandlers:86 - https://o427213.ingest.sentry.io:443 "POST /api/6142069/store/ HTTP/1.1" 200 41
[49]  2022-05-06 09:45:35.139 | DEBUG    | sentry_sdk.integrations.logging:sentry_patched_callhandlers:86 - https://o427213.ingest.sentry.io:443 "POST /api/6142069/store/ HTTP/1.1" 200 41
[49]  2022-05-06 09:45:35.168 | DEBUG    | sentry_sdk.integrations.logging:sentry_patched_callhandlers:86 - https://o427213.ingest.sentry.io:443 "POST /api/6142069/store/ HTTP/1.1" 429 45
[47]  2022-05-06 10:01:33.769 | INFO     | sentry_sdk.integrations.logging:sentry_patched_callhandlers:86 - Run run_VabE0RXY_H_nUpgKjqdGj for labelling function mill succeeded over 94088 results.
[49]  2022-05-06 10:07:03.140 | INFO     | sentry_sdk.integrations.logging:sentry_patched_callhandlers:86 - Run run_Z-wLr4kzxvoottduwO8N9 for labelling function mill succeeded over 94088 results.
[49]  2022-05-06 10:07:28.952 | INFO     | sentry_sdk.integrations.logging:sentry_patched_callhandlers:86 - Run run_dCduwH9_8xfP8BtTOJoJq for labelling function mill succeeded over 94088 results.
[47]  2022-05-06 10:14:48.774 | INFO     | sentry_sdk.integrations.logging:sentry_patched_callhandlers:86 - Run run_xz41CezifoshEn_JFlgWA for labelling function meadows_regex succeeded over 94088 results.
[47]  2022-05-06 10:15:05.112 | INFO     | sentry_sdk.integrations.logging:sentry_patched_callhandlers:86 - Run run_mPfgP4qwmBwKqXGjVVm6Q for labelling function meadows_regex succeeded over 94088 results.
[43]  2022-05-06 10:15:28.928 | INFO     | sentry_sdk.integrations.logging:sentry_patched_callhandlers:86 - Run run_23C-k8zJjZK17C73ukAa3 for labelling function meadows_regex succeeded over 94088 results.
[43]  2022-05-06 10:17:20.086 | INFO     | sentry_sdk.integrations.logging:sentry_patched_callhandlers:86 - Run run_GBQNIoX_PZk0shEa2qhe6 for labelling function carpark_id_fn succeeded over 94088 results.
[49]  2022-05-06 10:23:17.464 | INFO     | sentry_sdk.integrations.logging:sentry_patched_callhandlers:86 - Run run_7VrjHllZqm5kk8rUKNFUQ for labelling function and_space_n_flats succeeded over 94088 results.
[49]  2022-05-06 10:24:01.848 | INFO     | sentry_sdk.integrations.logging:sentry_patched_callhandlers:86 - Run run_C6L3AZgHwaolWaVob5_fq for labelling function begins_with_number_flat succeeded over 94088 results.
